<?xml version="1.0"?>
<!-- This URDF was automatically created by SolidWorks to URDF Exporter! Originally created by Stephen Brawner (brawner@gmail.com) 
     Commit Version: 1.6.0-4-g7f85cfe  Build Version: 1.6.7995.38578
     For more information, please see http://wiki.ros.org/sw_urdf_exporter -->
<robot
  name="wcurdf">
  <link
    name="base_link">
    
    <visual>
      <origin
        xyz="0 0 0"
        rpy="0 0 0" />
      <geometry>
        <mesh
          filename="package://wheelchair_description/meshes/base_link3.STL" />
      </geometry>
      <material
        name="">
        <color
          rgba="0 0.83921568627451 0.890196078431372 1" />
      </material>
    </visual>
    <collision>
      <origin
        xyz="0 0 0"
        rpy="0 0 0" />
      <geometry>
        <mesh
          filename="package://wheelchair_description/meshes/base_link3.STL" />
      </geometry>
    </collision>
  </link>
  <link
    name="wheel1">
    <inertial>
      <origin
        xyz="0.0748658745103095 -0.0291872044114263 -0.402522263649013"
        rpy="0 0 0" />
      <mass
        value="54.9780121890262" />
      <inertia
        ixx="0.415075874747108"
        ixy="7.18276450241275E-20"
        ixz="-2.21272662606604E-18"
        iyy="0.771547349598385"
        iyz="-2.18135030742223E-17"
        izz="0.415075874747108" />
    </inertial>
    <visual>
      <origin
        xyz="0 0 0"
        rpy="0 0 0" />
      <geometry>
        <mesh
          filename="package://wheelchair_description/meshes/wheel1.STL" />
      </geometry>
      <material
        name="">
        <color
          rgba="0.180392156862745 0.180392156862745 0.180392156862745 1" />
      </material>
    </visual>
    <collision>
      <origin
        xyz="0 0 0"
        rpy="0 0 0" />
      <geometry>
        <mesh
          filename="package://wheelchair_description/meshes/wheel1.STL" />
      </geometry>
    </collision>
  </link>
  <joint
    name="j1"
    type="continuous">
    <origin
      xyz="0 0 0"
      rpy="0 0 0" />
    <parent
      link="base_link" />
    <child
      link="wheel1" />
    <axis
      xyz="0 1 0" />
  </joint>
  <link
    name="wheel2">
    <inertial>
      <origin
        xyz="0.124865874510309 -0.0291715874614843 0.122477736350987"
        rpy="0 0 0" />
      <mass
        value="27.0429703133058" />
      <inertia
        ixx="0.107819500135783"
        ixy="2.14909898534325E-18"
        ixz="-5.93828263365939E-18"
        iyy="0.186832004337211"
        iyz="-4.29277370472307E-18"
        izz="0.107819500135783" />
    </inertial>
    <visual>
      <origin
        xyz="0 0 0"
        rpy="0 0 0" />
      <geometry>
        <mesh
          filename="package://wheelchair_description/meshes/wheel2.STL" />
      </geometry>
      <material
        name="">
        <color
          rgba="0.223529411764706 0.223529411764706 0.223529411764706 1" />
      </material>
    </visual>
    <collision>
      <origin
        xyz="0 0 0"
        rpy="0 0 0" />
      <geometry>
        <mesh
          filename="package://wheelchair_description/meshes/wheel2.STL" />
      </geometry>
    </collision>
  </link>
  <joint
    name="j2"
    type="continuous">
    <origin
      xyz="0 0 0"
      rpy="0 0 0" />
    <parent
      link="base_link" />
    <child
      link="wheel2" />
    <axis
      xyz="0 1 0" />
  </joint>
  <link
    name="wheel3">
    <inertial>
      <origin
        xyz="0.124865874510309 -0.709233057844671 0.122477736350988"
        rpy="0 0 0" />
      <mass
        value="27.0429703133058" />
      <inertia
        ixx="0.107819500135783"
        ixy="3.38853330767202E-19"
        ixz="-5.90304606305361E-18"
        iyy="0.186832004337211"
        iyz="-2.23197117192281E-16"
        izz="0.107819500135783" />
    </inertial>
    <visual>
      <origin
        xyz="0 0 0"
        rpy="0 0 0" />
      <geometry>
        <mesh
          filename="package://wheelchair_description/meshes/wheel3.STL" />
      </geometry>
      <material
        name="">
        <color
          rgba="0.223529411764706 0.223529411764706 0.223529411764706 1" />
      </material>
    </visual>
    <collision>
      <origin
        xyz="0 0 0"
        rpy="0 0 0" />
      <geometry>
        <mesh
          filename="package://wheelchair_description/meshes/wheel3.STL" />
      </geometry>
    </collision>
  </link>
  <joint
    name="j3"
    type="continuous">
    <origin
      xyz="0 0 0"
      rpy="0 0 0" />
    <parent
      link="base_link" />
    <child
      link="wheel3" />
    <axis
      xyz="0 1 0" />
  </joint>
  <link
    name="wheel4">
    <inertial>
      <origin
        xyz="0.0748658745103095 -0.709217440894731 -0.402522263649012"
        rpy="0 0 0" />
      <mass
        value="54.9780121890262" />
      <inertia
        ixx="0.415075874747108"
        ixy="-8.74872203773565E-18"
        ixz="-1.66424103725516E-17"
        iyy="0.771547349598384"
        iyz="-1.01109991506764E-15"
        izz="0.415075874747108" />
    </inertial>
    <visual>
      <origin
        xyz="0 0 0"
        rpy="0 0 0" />
      <geometry>
        <mesh
          filename="package://wheelchair_description/meshes/wheel4.STL" />
      </geometry>
      <material
        name="">
        <color
          rgba="0.180392156862745 0.180392156862745 0.180392156862745 1" />
      </material>
    </visual>
    <collision>
      <origin
        xyz="0 0 0"
        rpy="0 0 0" />
      <geometry>
        <mesh
          filename="package://wheelchair_description/meshes/wheel4.STL" />
      </geometry>
    </collision>
  </link>
  <joint
    name="j4"
    type="continuous">
    <origin
      xyz="0 0 0"
      rpy="0 0 0" />
    <parent
      link="base_link" />
    <child
      link="wheel4" />
    <axis
      xyz="0 1 0" />
  </joint>
  <link
    name="camera">
    <inertial>
      <origin
        xyz="-0.96263412548969 -0.369202322653078 -0.353868282254552"
        rpy="0 0 0" />
      <mass
        value="0.964143729308595" />
      <inertia
        ixx="0.00234832622275064"
        ixy="2.0202852485842E-19"
        ixz="1.01370657582998E-20"
        iyy="0.000119230074904324"
        iyz="2.00144573390879E-19"
        izz="0.00232747878836438" />
    </inertial>
    <visual>
      <origin
        xyz="0 0 0"
        rpy="0 0 0" />
      <geometry>
        <mesh
          filename="package://wheelchair_description/meshes/camera.STL" />
      </geometry>
      <material
        name="">
        <color
          rgba="1 0.458823529411765 0.458823529411765 1" />
      </material>
    </visual>
    <collision>
      <origin
        xyz="0 0 0"
        rpy="0 0 0" />
      <geometry>
        <mesh
          filename="package://wheelchair_description/meshes/camera.STL" />
      </geometry>
    </collision>
  </link>
  <joint
    name="f1"
    type="fixed">
    <origin
      xyz="0 0 0"
      rpy="0 0 0" />
    <parent
      link="base_link" />
    <child
      link="camera" />
    <axis
      xyz="0 0 0" />
  </joint>
  
  <transmission name="frontWheel_L_tran">
    <type>transmission_interface/SimpleTransmission</type>
    <joint name="wheel2">
      <hardwareInterface>hardware_interface/EffortJointInterface</hardwareInterface>
    </joint>
    <actuator name="frontWheel_L_actr">
      <hardwareInterface>hardware_interface/EffortJointInterface</hardwareInterface>
      <mechanicalReduction>1</mechanicalReduction>
    </actuator>
  </transmission>
  <transmission name="frontWheel_R_tran">
    <type>transmission_interface/SimpleTransmission</type>
    <joint name="wheel3">
      <hardwareInterface>hardware_interface/EffortJointInterface</hardwareInterface>
    </joint>
    <actuator name="frontWheel_R_actr">
      <hardwareInterface>hardware_interface/EffortJointInterface</hardwareInterface>
      <mechanicalReduction>1</mechanicalReduction>
    </actuator>
  </transmission>
  <transmission name="BackWheel_R_tran">
    <type>transmission_interface/SimpleTransmission</type>
    <joint name="wheel4">
      <hardwareInterface>hardware_interface/VelocityJointInterface</hardwareInterface>
    </joint>
    <actuator name="BackWheel_R_actr">
      <hardwareInterface>hardware_interface/VelocityJointInterface</hardwareInterface>
      <mechanicalReduction>1</mechanicalReduction>
    </actuator>
  </transmission>
  <transmission name="BackWheel_L_tran">
    <type>transmission_interface/SimpleTransmission</type>
    <joint name="wheel1">
      <hardwareInterface>hardware_interface/VelocityJointInterface</hardwareInterface>
    </joint>
    <actuator name="BackWheel_L_actr">
      <hardwareInterface>hardware_interface/VelocityJointInterface</hardwareInterface>
      <mechanicalReduction>1</mechanicalReduction>
    </actuator>
  </transmission>
</robot>
