<?xml version="1.0" ?>
<!-- =================================================================================== -->
<!-- |    This document was autogenerated by xacro from src/wheelchair_description/urdf/wheelchair.xacro | -->
<!-- |    EDITING THIS FILE BY HAND IS NOT RECOMMENDED                                 | -->
<!-- =================================================================================== -->
<robot name="wheelchair" xmlns:xacro="http://www.ros.org/wiki/xacro">
  <xacro:arg name="prefix" default=""/>
  <material name="dark_grey">
    <color rgba="0.2 0.2 0.2 1.0"/>
  </material>
  <material name="light_grey">
    <color rgba="0.4 0.4 0.4 1.0"/>
  </material>
  <material name="yellow">
    <color rgba="0.8 0.8 0.0 1.0"/>
  </material>
  <material name="black">
    <color rgba="0.15 0.15 0.15 1.0"/>
  </material>
  <gazebo>
    <plugin name="gz_ros2_control::GazeboSimROS2ControlPlugin" filename="libgz_ros2_control-system.so">
      <parameters>$(find wheelchair_description)/config/my_controllers.yaml</parameters>
    </plugin>
  </gazebo>
  <xacro:include filename="imu_sensor.xacro"/>
  <xacro:imu_sensor
    prefix="$(arg prefix)"
    parent="base_link"
    frame_id="imu"
    xyz_offset="0 0 0.006"
    rpy_offset="0 0 0"
    update_rate="15.0"
    topic_name="imu/data"/>
  <gazebo reference="base_link">
    <material>Gazebo/Yellow</material>
    <mu1>0.5</mu1>
    <mu2>0.5</mu2>

    <gravity>true</gravity>
  </gazebo>
  <gazebo reference="BackWheel_R">
    <material>Gazebo/Gray</material>
    <mu1>0.5</mu1>
    <mu2>0.5</mu2>

  </gazebo>
  <gazebo reference="BackWheel_L">
    <material>Gazebo/Gray</material>
    <mu1>0.5</mu1>
    <mu2>0.5</mu2>

  </gazebo>
  <gazebo reference="frontSupport_R">
    <material>Gazebo/Red</material>
    <mu1>0.001</mu1>
    <mu2>0.001</mu2>

    <gravity>true</gravity>
  </gazebo>
  <gazebo reference="frontWheel_R">
    <material>Gazebo/Gray</material>
    <mu1>0.5</mu1>
    <mu2>0.5</mu2>

  </gazebo>
  <gazebo reference="frontSupport_L">
    <material>Gazebo/Red</material>
    <mu1>0.001</mu1>
    <mu2>0.001</mu2>

    <gravity>true</gravity>
  </gazebo>
  <gazebo reference="frontWheel_L">
    <material>Gazebo/Gray</material>
    <mu1>0.5</mu1>
    <mu2>0.5</mu2>

  </gazebo>
  <transmission name="frontSupport_R_tran">
    <type>transmission_interface/SimpleTransmission</type>
    <joint name="joint_frontSupport_R">
      <hardwareInterface>hardware_interface/EffortJointInterface</hardwareInterface>
    </joint>
    <actuator name="frontSupport_R_actr">
      <hardwareInterface>hardware_interface/EffortJointInterface</hardwareInterface>
      <mechanicalReduction>1</mechanicalReduction>
    </actuator>
  </transmission>
  <transmission name="frontSupport_L_tran">
    <type>transmission_interface/SimpleTransmission</type>
    <joint name="joint_frontSupport_L">
      <hardwareInterface>hardware_interface/EffortJointInterface</hardwareInterface>
    </joint>
    <actuator name="frontSupport_L_actr">
      <hardwareInterface>hardware_interface/EffortJointInterface</hardwareInterface>
      <mechanicalReduction>1</mechanicalReduction>
    </actuator>
  </transmission>
  <transmission name="frontWheel_L_tran">
    <type>transmission_interface/SimpleTransmission</type>
    <joint name="joint_frontWheel_L">
      <hardwareInterface>hardware_interface/EffortJointInterface</hardwareInterface>
    </joint>
    <actuator name="frontWheel_L_actr">
      <hardwareInterface>hardware_interface/EffortJointInterface</hardwareInterface>
      <mechanicalReduction>1</mechanicalReduction>
    </actuator>
  </transmission>
  <transmission name="frontWheel_R_tran">
    <type>transmission_interface/SimpleTransmission</type>
    <joint name="joint_frontWheel_R">
      <hardwareInterface>hardware_interface/EffortJointInterface</hardwareInterface>
    </joint>
    <actuator name="frontWheel_R_actr">
      <hardwareInterface>hardware_interface/EffortJointInterface</hardwareInterface>
      <mechanicalReduction>1</mechanicalReduction>
    </actuator>
  </transmission>
  <transmission name="BackWheel_R_tran">
    <type>transmission_interface/SimpleTransmission</type>
    <joint name="joint_BackWheel_R">
      <hardwareInterface>hardware_interface/VelocityJointInterface</hardwareInterface>
    </joint>
    <actuator name="BackWheel_R_actr">
      <hardwareInterface>hardware_interface/VelocityJointInterface</hardwareInterface>
      <mechanicalReduction>1</mechanicalReduction>
    </actuator>
  </transmission>
  <transmission name="BackWheel_L_tran">
    <type>transmission_interface/SimpleTransmission</type>
    <joint name="joint_BackWheel_L">
      <hardwareInterface>hardware_interface/VelocityJointInterface</hardwareInterface>
    </joint>
    <actuator name="BackWheel_L_actr">
      <hardwareInterface>hardware_interface/VelocityJointInterface</hardwareInterface>
      <mechanicalReduction>1</mechanicalReduction>
    </actuator>
  </transmission>
  <material name="silver">
    <color rgba="0.700 0.700 0.700 1.000"/>
  </material>
  <link name="base_link">
    <inertial>
      <origin rpy="0 0 0" xyz="0.114536595580849 -0.00152408256990729 0.436779247326475"/>
      <mass value="447.276736142322"/>
      <inertia ixx="35.1897195522903" ixy="0.196649743016102" ixz="10.8933242975922" iyy="48.0925168138991" iyz="0.167249581771051" izz="32.2814889958827"/>
    </inertial>
    <visual>
      <origin rpy="0 0 0" xyz="0 0 0"/>
      <geometry>
        <mesh filename="package://wheelchair_description/meshes/base_link.STL"/>
      </geometry>
      <material name="">
        <color rgba="0.792156862745098 0.819607843137255 0.933333333333333 1"/>
      </material>
    </visual>
    <collision>
      <origin rpy="0 0 0" xyz="0 0 0"/>
      <geometry>
        <mesh filename="package://wheelchair_description/meshes/base_link.STL"/>
      </geometry>
    </collision>
  </link>
  <link name="BackWheel_R">
    <inertial>
      <origin rpy="0 0 0" xyz="-0.00169441028748185 0.00740469367557789 0.013256206081967"/>
      <mass value="6.27376052921882"/>
      <inertia ixx="0.0484757628359798" ixy="1.61559943577015E-33" ixz="4.33680868994202E-19" iyy="0.0484757628359798" iyz="2.40741243048404E-34" izz="0.091819799725367"/>
    </inertial>
    <visual>
      <origin rpy="0 0 0" xyz="0 0 0"/>
      <geometry>
        <mesh filename="package://wheelchair_description/meshes/BackWheel_R.STL"/>
      </geometry>
      <material name="">
        <color rgba="0.792156862745098 0.819607843137255 0.933333333333333 1"/>
      </material>
    </visual>
    <collision>
      <origin rpy="0 0 0" xyz="0 0 0"/>
      <geometry>
        <mesh filename="package://wheelchair_description/meshes/BackWheel_R.STL"/>
      </geometry>
    </collision>
  </link>
  <joint name="joint_BackWheel_R" type="continuous">
    <origin rpy="1.5708 0 0" xyz="0.0016944 -0.22678 0.092595"/>
    <parent link="base_link"/>
    <child link="BackWheel_R"/>
    <axis xyz="0 0 -1"/>
  </joint>
  <link name="BackWheel_L">
    <inertial>
      <origin rpy="0 0 0" xyz="0.000656843796669526 0.00740469367557789 -0.0568128863805126"/>
      <mass value="6.27376052921882"/>
      <inertia ixx="0.0484757628359798" ixy="-3.01150799459453E-34" ixz="-1.10588621593521E-17" iyy="0.0484757628359798" iyz="3.50584621014999E-34" izz="0.091819799725367"/>
    </inertial>
    <visual>
      <origin rpy="0 0 0" xyz="0 0 0"/>
      <geometry>
        <mesh filename="package://wheelchair_description/meshes/BackWheel_L.STL"/>
      </geometry>
      <material name="">
        <color rgba="0.792156862745098 0.819607843137255 0.933333333333333 1"/>
      </material>
    </visual>
    <collision>
      <origin rpy="0 0 0" xyz="0 0 0"/>
      <geometry>
        <mesh filename="package://wheelchair_description/meshes/BackWheel_L.STL"/>
      </geometry>
    </collision>
  </link>
  <joint name="joint_BackWheel_L" type="continuous">
    <origin rpy="1.5708 0 0" xyz="-0.00065684 0.18322 0.092595"/>
    <parent link="base_link"/>
    <child link="BackWheel_L"/>
    <axis xyz="0 0 -1"/>
  </joint>
  <link name="frontSupport_R">
    <inertial>
      <origin rpy="0 0 0" xyz="0.0135676093823349 1.95081814838016E-05 -0.0379084155560667"/>
      <mass value="2.84122714047001"/>
      <inertia ixx="0.0101880379705202" ixy="-8.52702502935724E-07" ixz="0.00344214521935034" iyy="0.0107810768742505" iyz="4.94928706600269E-06" izz="0.0054426407340849"/>
    </inertial>
    <visual>
      <origin rpy="0 0 0" xyz="0 0 0"/>
      <geometry>
        <mesh filename="package://wheelchair_description/meshes/frontSupport_R.STL"/>
      </geometry>
      <material name="">
        <color rgba="0.792156862745098 0.819607843137255 0.933333333333333 1"/>
      </material>
    </visual>
    <collision>
      <origin rpy="0 0 0" xyz="0 0 0"/>
      <geometry>
        <mesh filename="package://wheelchair_description/meshes/frontSupport_R.STL"/>
      </geometry>
    </collision>
  </link>
  <joint name="joint_frontSupport_R" type="revolute">
    <origin rpy="0 0 0" xyz="0.59999 -0.2275 0.21923"/>
    <parent link="base_link"/>
    <child link="frontSupport_R"/>
    <axis xyz="0 0 1"/>
    <limit effort="1000.0" lower="-10" upper="10" velocity="0.5"/>
  </joint>
  <link name="frontWheel_R">
    <inertial>
      <origin rpy="0 0 0" xyz="-0.00178720463504489 0.00740469367557794 -0.0183364245234532"/>
      <mass value="3.41412581628871"/>
      <inertia ixx="0.0148158834902695" ixy="-2.49110762826259E-34" ixz="-3.25938278103455E-17" iyy="0.0148158834902695" iyz="5.57893209289991E-20" izz="0.02684356423057"/>
    </inertial>
    <visual>
      <origin rpy="0 0 0" xyz="0 0 0"/>
      <geometry>
        <mesh filename="package://wheelchair_description/meshes/frontWheel_R.STL"/>
      </geometry>
      <material name="">
        <color rgba="0.792156862745098 0.819607843137255 0.933333333333333 1"/>
      </material>
    </visual>
    <collision>
      <origin rpy="0 0 0" xyz="0 0 0"/>
      <geometry>
        <mesh filename="package://wheelchair_description/meshes/frontWheel_R.STL"/>
      </geometry>
    </collision>
  </link>
  <joint name="joint_frontWheel_R" type="continuous">
    <origin rpy="1.5708 0 0.0014378" xyz="0.080904 -0.01822 -0.17105"/>
    <parent link="frontSupport_R"/>
    <child link="frontWheel_R"/>
    <axis xyz="0 0 -1"/>
  </joint>
  <link name="frontSupport_L">
    <inertial>
      <origin rpy="0 0 0" xyz="0.0135676093823347 1.95081814836906E-05 -0.0379084155560666"/>
      <mass value="2.84122714047"/>
      <inertia ixx="0.0101880379705202" ixy="-8.52702502926847E-07" ixz="0.00344214521935032" iyy="0.0107810768742504" iyz="4.9492870659887E-06" izz="0.00544264073408488"/>
    </inertial>
    <visual>
      <origin rpy="0 0 0" xyz="0 0 0"/>
      <geometry>
        <mesh filename="package://wheelchair_description/meshes/frontSupport_L.STL"/>
      </geometry>
      <material name="">
        <color rgba="0.792156862745098 0.819607843137255 0.933333333333333 1"/>
      </material>
    </visual>
    <collision>
      <origin rpy="0 0 0" xyz="0 0 0"/>
      <geometry>
        <mesh filename="package://wheelchair_description/meshes/frontSupport_L.STL"/>
      </geometry>
    </collision>
  </link>
  <joint name="joint_frontSupport_L" type="revolute">
    <origin rpy="0 0 0" xyz="0.59999 0.2275 0.21923"/>
    <parent link="base_link"/>
    <child link="frontSupport_L"/>
    <axis xyz="0 0 1"/>
    <limit effort="1000.0" lower="-10" upper="10" velocity="0.5"/>
  </joint>
  <link name="frontWheel_L">
    <inertial>
      <origin rpy="0 0 0" xyz="0.000822104499104581 0.00740469367557794 -0.0183401546141397"/>
      <mass value="3.41412581628871"/>
      <inertia ixx="0.0148158834902696" ixy="-9.4039548065783E-35" ixz="7.9959910220806E-19" iyy="0.0148158834902695" iyz="5.57893209289991E-20" izz="0.02684356423057"/>
    </inertial>
    <visual>
      <origin rpy="0 0 0" xyz="0 0 0"/>
      <geometry>
        <mesh filename="package://wheelchair_description/meshes/frontWheel_L.STL"/>
      </geometry>
      <material name="">
        <color rgba="0.792156862745098 0.819607843137255 0.933333333333333 1"/>
      </material>
    </visual>
    <collision>
      <origin rpy="0 0 0" xyz="0 0 0"/>
      <geometry>
        <mesh filename="package://wheelchair_description/meshes/frontWheel_L.STL"/>
      </geometry>
    </collision>
  </link>
  <joint name="joint_frontWheel_L" type="continuous">
    <origin rpy="1.5708 0 0.0014378" xyz="0.078295 -0.018228 -0.17105"/>
    <parent link="frontSupport_L"/>
    <child link="frontWheel_L"/>
    <axis xyz="0 0 -1"/>
  </joint>
  <link name="dummy_IMU_link">
    <inertial>
      <origin xyz="0 0 0" rpy="0 0 0"/>
      <mass value="0.001"/>
      <inertia ixx="0.0001" ixy="0" ixz="0" iyy="0.0001" iyz="0" izz="0.0001"/>
    </inertial>
  </link>

<!-- Joint connecting base_link to dummy link -->
  <joint name="joint_dummy_IMU" type="fixed">
  <!-- Adjust the origin as needed for positioning -->
    <origin xyz="0.48593 0 0.21221" rpy="0 0 0"/>
    <parent link="base_link"/>
    <child link="dummy_IMU_link"/>
  </joint>
  <link name="IMU">
    <inertial>
      <origin rpy="0 0 0" xyz="0.00166469876107445 -4.16333634234434E-17 0.00804691990209122"/>
      <mass value="0.0337817410992299"/>
      <inertia ixx="4.25090846017802E-06" ixy="-6.54077808907863E-08" ixz="5.4131140322816E-08" iyy="3.73423045571171E-06" iyz="-2.72020403770311E-21" izz="7.51401299696132E-06"/>
    </inertial>
    <visual>
      <origin rpy="0 0 0" xyz="0 0 0"/>
      <geometry>
        <mesh filename="package://wheelchair_description/meshes/IMU.STL"/>
      </geometry>
      <material name="">
        <color rgba="0.792156862745098 0.819607843137255 0.933333333333333 1"/>
      </material>
    </visual>
    <collision>
      <origin rpy="0 0 0" xyz="0 0 0"/>
      <geometry>
        <mesh filename="package://wheelchair_description/meshes/IMU.STL"/>
      </geometry>
    </collision>
  </link>
  <joint name="joint_IMU" type="fixed">
    <origin rpy="0 0 0" xyz="0 0 0"/>
    <parent link="dummy_IMU_link"/>
    <child link="IMU"/>
    <gazebo>
      <preserveFixedJoint>true</preserveFixedJoint>
    </gazebo>
    <axis xyz="0 0 0"/>
  </joint>

<!-- Joint connecting base_link to dummy link -->
  <link name="dummy_frontCam_link">
    <inertial>
      <origin xyz="0 0 0" rpy="0 0 0"/>
      <mass value="0.001"/>
      <inertia ixx="0.0001" ixy="0" ixz="0" iyy="0.0001" iyz="0" izz="0.0001"/>
    </inertial>
  </link>
  <joint name="joint_dummy_frontCam" type="fixed">
  <!-- Adjust the origin as needed for positioning -->
    <origin xyz="0.55611 -0.2411 0.64417" rpy="0 0 0"/>
    <parent link="base_link"/>
    <child link="dummy_frontCam_link"/>
  </joint>
  <link name="frontCam">
    <inertial>
      <origin rpy="0 0 0" xyz="-0.00734413497152947 -0.00365798760354635 0.0108401434966239"/>
      <mass value="0.0447521305742423"/>
      <inertia ixx="2.73620547322335E-05" ixy="2.8047302259071E-05" ixz="1.17470701926149E-05" iyy="3.94471940669399E-05" iyz="2.44349975033884E-05" izz="2.72774944848882E-05"/>
    </inertial>
    <visual>
      <origin rpy="0 0 0" xyz="0 0 0"/>
      <geometry>
        <mesh filename="package://wheelchair_description/meshes/frontCam.STL"/>
      </geometry>
      <material name="">
        <color rgba="0.792156862745098 0.819607843137255 0.933333333333333 1"/>
      </material>
    </visual>
    <collision>
      <origin rpy="0 0 0" xyz="0 0 0"/>
      <geometry>
        <mesh filename="package://wheelchair_description/meshes/frontCam.STL"/>
      </geometry>
    </collision>
  </link>
  <joint name="joint_frontCam" type="fixed">
  <!-- Adjust the origin as needed for positioning -->
    <origin xyz="0 0 0" rpy="0 0 0"/>
    <parent link="dummy_frontCam_link"/>
    <child link="frontCam"/>
  </joint>
  <joint name="camera_optical_joint" type="fixed">
    <parent link="frontCam"/>
    <child link="camera_link_optical"/>
    <origin xyz="0 0 0" rpy="-1.57 0 -1.57"/>
  </joint>

  <link name="camera_link_optical"></link>



  <gazebo reference="frontCam">
    <material>Gazebo/Red</material>

    <sensor name="camera" type="depth">
      <pose> 0 0 0 0 0 0 </pose>
      <visualize>true</visualize>
      <update_rate>10</update_rate>
      <camera>
        <camera_info_topic>camera/camera_info</camera_info_topic>
        <horizontal_fov>1.089</horizontal_fov>
        <image>
          <format>B8R8G8</format>
          <width>640</width>
          <height>480</height>
        </image>
        <clip>
          <near>0.05</near>
          <far>8.0</far>
        </clip>
      </camera>
      <topic>camera/image_raw</topic>
      <gz_frame_id>camera_link_optical</gz_frame_id>
    </sensor>
  </gazebo>
  
   <gazebo>
     <plugin name="gz::sim::systems::DiffDrive" filename="gz-sim-diff-drive-system">
        <left_joint>joint_BackWheel_L</left_joint>
        <right_joint>joint_BackWheel_R</right_joint>
        <wheel_separation>0.55</wheel_separation>
        <wheel_radius>0.17</wheel_radius>
        <max_linear_acceleration>0.4</max_linear_acceleration>
        <topic>cmd_vel</topic>
        <child_frame_id>base_link</child_frame_id>
        <frame_id>odom</frame_id>
        <odom_topic>odom</odom_topic>
        <tf_topic>/tf</tf_topic>
      </plugin>
  </gazebo>
</robot>
